<?xml version="1.0" encoding="utf-8"?>

<robot
  name="panter">
<!-- CHASIS -->

  <link name="CH">
    <inertial>
      <origin
        xyz="-0.00880173011979828 -0.4226795868207859 0.673550824362744"
        rpy="0 0 0" />
      <mass
        value="343" />
      <inertia
        ixx="210.9428277"
        ixy="0"
        ixz="0"
        iyy="79.04789433"
        iyz="0"
        izz="260.5199333" />
    </inertial>
    <visual>
      <origin
        xyz="0 0 0"
        rpy="0 0 0" />
      <geometry>
        <mesh
          filename="package://description_pkg/meshes/CH.STL" />
      </geometry>
      <material
        name="">
        <color
          rgba="0.4 0.4 0.4 1" />
      </material>
    </visual>
    <collision>
      <origin
        xyz="0 -0.44 0.675"
        rpy="0 0 0" />
      <geometry>
        <box size="1.5 2.62 0.718"/>
        
      </geometry>
    </collision>
  </link>

<!--        #### EJE DELANTERO IZQUIERDA ####        -->

<!-- AMORTIGUADOR DELANTERO IZQUIERDO -->

  <link name="SD01_IZQ">
    <inertial>
      <origin
        xyz="0.023095387698848 0.0466016681758654 -0.187519014527033"
        rpy="0 0 0" />
      <mass
        value="1.56443700619495" />
      <inertia
        ixx="0.0054896363326847"
        ixy="-0.000185514968568694"
        ixz="0.00075298015942053"
        iyy="0.00531762879813639"
        iyz="0.00114868462288693"
        izz="0.00101605585965138" />
    </inertial>
    <visual>
      <origin
        xyz="0 0 0"
        rpy="0 0 0" />
      <geometry>
        <mesh
          filename="package://description_pkg/meshes/SD01_IZQ.STL" />
      </geometry>
      <material
        name="">
        <color
          rgba="0.752941176470588 0.752941176470588 0.752941176470588 1" />
      </material>
    </visual>
    <collision>
      <origin
        xyz="0 0 0"
        rpy="0 0 0" />
      <geometry>
        <mesh
          filename="package://description_pkg/meshes/SD01_IZQ.STL" />
      </geometry>
    </collision>
  </link>

  <joint name="SD01_IZQ_sup_joint" type="revolute">
    <origin
      xyz="0.364 -1.4598 0.85354"
      rpy="0 0 -1.5708" />
    <parent
      link="CH" />
    <child
      link="SD01_IZQ" />
    <axis
      xyz="1 0 0" />
    <limit effort="1.0" velocity="5.0" lower="-3.14" upper="3.14"/>
  </joint>

<!-- BRAZO SUPERIOR DELANTERO IZQUIERDO -->

  <link name="SD02_IZQ">
    <inertial>
      <origin
        xyz="-0.109382785122553 0.00538487649739164 -0.016693818528262"
        rpy="0 0 0" />
      <mass
        value="0.622420648905112" />
      <inertia
        ixx="0.00677202938721807"
        ixy="-0.00032427855560881"
        ixz="3.65258159557858E-05"
        iyy="0.00111523663422429"
        iyz="0.00191718137163241"
        izz="0.00655957488261609" />
    </inertial>
    <visual>
      <origin
        xyz="0 0 0"
        rpy="0 0 0" />
      <geometry>
        <mesh
          filename="package://description_pkg/meshes/SD02_IZQ.STL" />
      </geometry>
      <material
        name="">
        <color
          rgba="0.752941176470588 0.752941176470588 0.752941176470588 1" />
      </material>
    </visual>
    <collision>
      <origin
        xyz="0 0 0"
        rpy="0 0 0" />
      <geometry>
        <mesh
          filename="package://description_pkg/meshes/SD02_IZQ.STL" />
      </geometry>
    </collision>
  </link>

  <joint name="SD02_IZQ_CH_joint" type="revolute">
    <origin
      xyz="0.1865 -1.6482 0.53091"
      rpy="0 0 -1.5708" />
    <parent
      link="CH" />
    <child
      link="SD02_IZQ" />
    <axis
      xyz="1 0 0" />
      <!-- xyz="0.069756 0.99756 0" /> -->
    <limit effort="1.0" velocity="5.0" lower="-3.14" upper="3.14"/>
  </joint>

<!-- BRAZO INFERIOR DELANTERO IZQUIERDO -->

  <link name="SD03_IZQ">
    <inertial>
      <origin
        xyz="-0.097367551528877 0.158067753702783 -0.0696606835357823"
        rpy="0 0 0" />
      <mass
        value="0.468898614819818" />
      <inertia
        ixx="0.00505911557852378"
        ixy="-0.000121765335801827"
        ixz="1.81818642259916E-05"
        iyy="0.00122147601558512"
        iyz="0.00174136109600662"
        izz="0.00479917105508991" />
    </inertial>
    <visual>
      <origin
        xyz="0 0 0"
        rpy="0 0 0" />
      <geometry>
        <mesh
          filename="package://description_pkg/meshes/SD03_IZQ.STL" />
      </geometry>
      <material
        name="">
        <color
          rgba="0.752941176470588 0.752941176470588 0.752941176470588 1" />
      </material>
    </visual>
    <collision>
      <origin
        xyz="0 0 0"
        rpy="0 0 0" />
      <geometry>
        <mesh
          filename="package://description_pkg/meshes/SD03_IZQ.STL" />
      </geometry>
    </collision>
  </link>

  <joint name="SD03_IZQ_CH_joint" type="revolute">
    <parent link="CH"/>
    <child link="SD03_IZQ"/>
    <!-- <axis xyz="1 0 0" /> -->
    <axis xyz="1 0 0.07"/>
    <!-- hay que ajustar el eje sobre el que gira, no esta alineado con x, pero con solid lo podemos obtener  .069756 -->
    <limit lower="-3.14159" upper="3.14159" velocity="50.0" effort="1000.0"/>
    <origin
        xyz="0.151 -1.6306 0.37054"
        rpy="0 0 -1.5708" />
  </joint>


<!-- MANGUETA DELANTERA IZQUIERDA -->

  <link name="MGD_IZQ">
    <inertial>
      <origin
        xyz="-0.00497345711760122 -0.210444823308728 0.028708631857455"
        rpy="0 0 0" />
      <mass
        value="0.657785044151253" />
      <inertia
        ixx="0.000818666431242726"
        ixy="6.87964117180795E-06"
        ixz="0.000112075156886058"
        iyy="0.00160628936815674"
        iyz="-2.77497675092315E-05"
        izz="0.00115594236415572" />
    </inertial>
    <visual>
      <origin
        xyz="0 0 0"
        rpy="0 0 0" />
      <geometry>
        <mesh
          filename="package://description_pkg/meshes/MGD_IZQ.STL" />
      </geometry>
      <material
        name="">
        <color
          rgba="0.792156862745098 0.819607843137255 0.933333333333333 1" />
      </material>
    </visual>
    <collision>
      <origin
        xyz="0 0 0"
        rpy="0 0 0" />
      <geometry>
        <mesh
          filename="package://description_pkg/meshes/MGD_IZQ.STL" />
      </geometry>
    </collision>
  </link>

  <joint name="MGD_IZQ_joint" type="revolute">
    <origin
      xyz="-0.11217 0.52087 -0.23886"
      rpy="0 0 0" />
    <parent
      link="SD02_IZQ" />
    <child
      link="MGD_IZQ" />
    <axis
      xyz="0 0 1" />
      <limit effort="50.0" velocity="1.0" lower="-0.52" upper="0.52"/>
  </joint>

<!-- RUEDA DELANTERA IZQUIERDA -->

  <link name="ED_IZQ">
    <inertial>
      <origin
        xyz="9.83891827921468E-06 -0.0201678086647318 0.00124512879040783"
        rpy="0 0 0" />
      <mass
        value="29.1393624990723" />
      <inertia
        ixx="0.813594658177696"
        ixy="6.54522235780315E-08"
        ixz="-6.14314543670018E-09"
        iyy="1.43775571114071"
        iyz="-0.0383150788672202"
        izz="0.815946712920848" />
    </inertial>
    <visual>
      <origin
        xyz="0 0 0"
        rpy="1.5707 0 0" />
      <geometry>
        <mesh
          filename="package://description_pkg/meshes/ED_IZQ.STL" />
      </geometry>
      <material
        name="">
        <color
          rgba="0.1 0.1 0.1 1" />
      </material>
    </visual>
    <collision>
      <origin
        xyz="0 0.0075 0"
        rpy="0 1.5707 1.5707" />
      <geometry>
        <cylinder radius="0.343" length="0.23"/>
        
      </geometry>
    </collision>
  </link>

  <joint name="ED_IZQ_joint" type="revolute">
    <origin
      xyz="0 0 0"
      rpy="0 0 0" />
    <parent
      link="MGD_IZQ" />
    <child
      link="ED_IZQ" />
    <axis
      xyz="0 1 0" />

      <limit effort="1.0" velocity="5.0" lower="-10000000000000000" upper="10000000000000000"/>

  </joint>
  
<!--        #### EJE DELANTERO DERECHA ####        -->

<!-- AMORTIGUADOR DELANTERO DERECHO -->

  <link name="SD01_DCH">
    <inertial>
      <origin
        xyz="0.0147151277156394 -0.0466016638374874 -0.188936395717115"
        rpy="0 0 0" />
      <mass
        value="1.5644373485476" />
      <inertia
        ixx="0.00547351601733842"
        ixy="0.0002025684338576"
        ixz="0.000799273132675563"
        iyy="0.00531762933682683"
        iyz="-0.0011458003645297"
        izz="0.00103217687096616" />
    </inertial>
    <visual>
      <origin
        xyz="0 0 0"
        rpy="0 0 0" />
      <geometry>
        <mesh
          filename="package://description_pkg/meshes/SD01_DCH.STL" />
      </geometry>
      <material
        name="">
        <color
          rgba="0.752941176470588 0.752941176470588 0.752941176470588 1" />
      </material>
    </visual>
    <collision>
      <origin
        xyz="0 0 0"
        rpy="0 0 0" />
      <geometry>
        <mesh
          filename="package://description_pkg/meshes/SD01_DCH.STL" />
      </geometry>
    </collision>
  </link>

  <joint name="SD01_DCH_sup_joint" type="revolute">
    <origin
      xyz="-0.364 -1.4682 0.85496"
      rpy="0 0 -1.5708" />
    <parent
      link="CH" />
    <child
      link="SD01_DCH" />
    <axis
      xyz="1 0 0" />
    <limit effort="1.0" velocity="5.0" lower="-3.14" upper="3.14"/>
  </joint>

<!-- BRAZO SUPERIOR DELANTERO DERECHO -->

  <link name="SD02_DCH">
    <inertial>
      <origin
        xyz="-0.100708620793033 -0.178807887505557 -0.0713964836359323"
        rpy="0 0 0" />
      <mass
        value="0.335019981141928" />
      <inertia
        ixx="0.00342642521801625"
        ixy="-0.000175463505193739"
        ixz="-8.53632722802387E-05"
        iyy="0.000560176153155334"
        iyz="-0.00101420516690993"
        izz="0.00324706649765957" />
    </inertial>
    <visual>
      <origin
        xyz="0 0 0"
        rpy="0 0 0" />
      <geometry>
        <mesh
          filename="package://description_pkg/meshes/SD02_DCH.STL" />
      </geometry>
      <material
        name="">
        <color
          rgba="0.752941176470588 0.752941176470588 0.752941176470588 1" />
      </material>
    </visual>
    <collision>
      <origin
        xyz="0 0 0"
        rpy="0 0 0" />
      <geometry>
        <mesh
          filename="package://description_pkg/meshes/SD02_DCH.STL" />
      </geometry>
    </collision>
  </link>

  <joint name="SD02_DCH_CH_joint" type="revolute">
    <origin
      xyz="-0.1865 -1.6482 0.53091"
      rpy="0 0 -1.5708" />
    <parent
      link="CH" />
    <child
      link="SD02_DCH" />
    <axis
      xyz="1 0 0" />
    <limit effort="1.0" velocity="5.0" lower="-3.14" upper="3.14"/>
  </joint>

<!-- BRAZO INFERIOR DELANTERO DERECHO -->

  <link name="SD03_DCH">
    <inertial>
      <origin
        xyz="-0.0979518472036578 -0.169078002158508 -0.0764949344668193"
        rpy="0 0 0" />
      <mass
        value="0.395241260034587" />
      <inertia
        ixx="0.00503011023626271"
        ixy="0.000168676429607526"
        ixz="4.78400238798921E-05"
        iyy="0.00114327113657789"
        iyz="-0.00177766605683892"
        izz="0.00461706807689286" />
    </inertial>
    <visual>
      <origin
        xyz="0 0 0"
        rpy="0 0 0" />
      <geometry>
        <mesh
          filename="package://description_pkg/meshes/SD03_DCH.STL" />
      </geometry>
      <material
        name="">
        <color
          rgba="0.752941176470588 0.752941176470588 0.752941176470588 1" />
      </material>
    </visual>
    <collision>
      <origin
        xyz="0 0 0"
        rpy="0 0 0" />
      <geometry>
        <mesh
          filename="package://description_pkg/meshes/SD03_DCH.STL" />
      </geometry>
    </collision>
  </link>

  <joint name="SD03_DCH_CH_joint" type="revolute">
    <origin
      xyz="-0.151 -1.6306 0.37054"
      rpy="0 0 -1.5708" />
    <parent
      link="CH" />
    <child
      link="SD03_DCH" />
    <axis
      xyz="1 0 0" />
    <limit effort="1.0" velocity="5.0" lower="-3.14" upper="3.14"/>
  </joint>

<!-- MANGUETA DELANTERA DERECHA -->

  <link name="MGD_DCH">
    <inertial>
      <origin
        xyz="-0.00499672613858615 0.101475946327662 0.0231953048014176"
        rpy="0 0 0" />
      <mass
        value="0.328788737283037" />
      <inertia
        ixx="0.000408973712801148"
        ixy="-1.51590957094099E-05"
        ixz="5.49889371726592E-05"
        iyy="0.000807927110139834"
        iyz="-2.30270273360574E-05"
        izz="0.000572215537021713" />
    </inertial>
    <visual>
      <origin
        xyz="0 0 0"
        rpy="0 0 0" />
      <geometry>
        <mesh
          filename="package://description_pkg/meshes/MGD_DCH.STL" />
      </geometry>
      <material
        name="">
        <color
          rgba="0.792156862745098 0.819607843137255 0.933333333333333 1" />
      </material>
    </visual>
    <collision>
      <origin
        xyz="0 0 0"
        rpy="0 0 0" />
      <geometry>
        <mesh
          filename="package://description_pkg/meshes/MGD_DCH.STL" />
      </geometry>
    </collision>
  </link>

  <joint name="MGD_DCH_joint" type="revolute">
    <origin
      xyz="-0.11198 -0.51968 -0.24274"
      rpy="0 0 0" />
    <parent
      link="SD02_DCH" />
    <child
      link="MGD_DCH" />
    <axis
      xyz="0 0 1" />
      <limit effort="50" velocity="1.0" lower="-0.52" upper="0.52"/>
  </joint>

<!-- RUEDA DELANTERA DERECHA -->

  <link name="ED_DCH">
    <inertial>
      <origin
        xyz="2.29121924788522E-06 0.0201749464629289 0.00146310372559588"
        rpy="0 0 0" />
      <mass
        value="29.1428305698025" />
      <inertia
        ixx="0.813595259424299"
        ixy="1.6609911692007E-08"
        ixz="1.60980609943066E-09"
        iyy="1.43679321483636"
        iyz="0.0454494090796915"
        izz="0.816909826703764" />
    </inertial>
    <visual>
      <origin
        xyz="0 0 0"
        rpy="-1.5707 0 0" />
      <geometry>
        <mesh
          filename="package://description_pkg/meshes/ED_DCH.STL" />
      </geometry>
      <material
        name="">
        <color
          rgba="0.1 0.1 0.1 1" />
      </material>
    </visual>
    <collision>
      <origin
        xyz="0 -0.0065 0"
        rpy="0 1.5707 1.5707" />
      <geometry>
        <cylinder radius="0.343" length="0.23"/>
      </geometry>
    </collision>
  </link>

  <joint name="ED_DCH_joint" type="revolute">
    <origin
      xyz="0 0 0"
      rpy="0 0 0" />
    <parent
      link="MGD_DCH" />
    <child
      link="ED_DCH" />
    <axis
      xyz="0 1 0" />
    <limit effort="1.0" velocity="5.0" lower="-10000000000000000" upper="10000000000000000"/>

  </joint>

<!--        #### EJE TRASERO IZQUIERDA ####        -->

<!-- AMORTIGUADOR TRASERO IZQUIERDO -->

  <link name="ST01_IZQ">
    <inertial>
      <origin
        xyz="0.00849916904573988 0.0657819927228204 -0.159438279696458"
        rpy="0 0 0" />
      <mass
        value="1.68652397926041" />
      <inertia
        ixx="0.00633380015599702"
        ixy="-1.45261475353967E-05"
        ixz="3.52667266964353E-05"
        iyy="0.0055250803137682"
        iyz="0.0019468091581656"
        izz="0.00160836691478163" />
    </inertial>
    <visual>
      <origin
        xyz="0 0 0"
        rpy="0 0 0" />
      <geometry>
        <mesh
          filename="package://description_pkg/meshes/ST01_IZQ.STL" />
      </geometry>
      <material
        name="">
        <color
          rgba="0.752941176470588 0.752941176470588 0.752941176470588 1" />
      </material>
    </visual>
    <collision>
      <origin
        xyz="0 0 0"
        rpy="0 0 0" />
      <geometry>
        <mesh
          filename="package://description_pkg/meshes/ST01_IZQ.STL" />
      </geometry>
    </collision>
  </link>

  <joint name="ST01_IZQ_sup_joint" type="revolute">
    <origin
      xyz="0.3275 0.66468 0.79122"
      rpy="0 0 -1.5708" />
    <parent
      link="CH" />
    <child
      link="ST01_IZQ" />
    <axis
      xyz="1 0 0" />
    <limit effort="1.0" velocity="5.0" lower="-3.14" upper="3.14"/>
  </joint>

<!-- BRAZO SUPERIOR TRASERO IZQUIERDO -->

  <link name="ST02_IZQ">
    <inertial>
      <origin
        xyz="0.150000005167412 0.17487915113979 -0.0332493411124752"
        rpy="0 0 0" />
      <mass
        value="0.816782909187791" />
      <inertia
        ixx="0.00805847541687784"
        ixy="9.94042597564868E-10"
        ixz="4.393272678471E-09"
        iyy="0.00136969060130727"
        iyz="0.00150446688084042"
        izz="0.00869514722257052" />
    </inertial>
    <visual>
      <origin
        xyz="0 0 0"
        rpy="0 0 0" />
      <geometry>
        <mesh
          filename="package://description_pkg/meshes/ST02_IZQ.STL" />
      </geometry>
      <material
        name="">
        <color
          rgba="0.752941176470588 0.752941176470588 0.752941176470588 1" />
      </material>
    </visual>
    <collision>
      <origin
        xyz="0 0 0"
        rpy="0 0 0" />
      <geometry>
        <mesh
          filename="package://description_pkg/meshes/ST02_IZQ.STL" />
      </geometry>
    </collision>
  </link>

  <joint name="ST02_IZQ_CH_joint" type="revolute">
    <origin
      xyz="0.19 0.80618 0.45222"
      rpy="0 0 -1.5708" />
    <parent
      link="CH" />
    <child
      link="ST02_IZQ" />
    <axis
      xyz="1 0 0" />
    <limit effort="1.0" velocity="5.0" lower="-3.14" upper="3.14"/>
  </joint>

<!-- BRAZO INFERIOR TRASERO IZQUIERDO -->

  <link name="ST03_IZQ">
    <inertial>
      <origin
        xyz="0.149999999999999 0.164533605888154 -0.0525148439282281"
        rpy="0 0 0" />
      <mass
        value="0.341061626894355" />
      <inertia
        ixx="0.00227935928137915"
        ixy="9.86423410377996E-18"
        ixz="-2.42692932918681E-18"
        iyy="0.000532010440822694"
        iyz="0.000627611706470002"
        izz="0.00233995796668448" />
    </inertial>
    <visual>
      <origin
        xyz="0 0 0"
        rpy="0 0 0" />
      <geometry>
        <mesh
          filename="package://description_pkg/meshes/ST03_IZQ.STL" />
      </geometry>
      <material
        name="">
        <color
          rgba="0.752941176470588 0.752941176470588 0.752941176470588 1" />
      </material>
    </visual>
    <collision>
      <origin
        xyz="0 0 0"
        rpy="0 0 0" />
      <geometry>
        <mesh
          filename="package://description_pkg/meshes/ST03_IZQ.STL" />
      </geometry>
    </collision>
  </link>

  <joint name="ST03_IZQ_CH_joint" type="revolute">
    <origin
      xyz="0.178 0.80618 0.34222"
      rpy="0 0 -1.5708" />
    <parent
      link="CH" />
    <child
      link="ST03_IZQ" />
    <axis
      xyz="1 0 0" />
    <limit effort="1.0" velocity="5.0" lower="-3.14" upper="3.14"/>
  </joint>

<!-- MANGUETA TRASERA IZQUIERDA -->

  <link name="MGT_IZQ">
    <inertial>
      <origin
        xyz="0.069988106311084 -0.0306022880154865 5.74031686517706E-07"
        rpy="0 0 0" />
      <mass
        value="0.451405474193324" />
      <inertia
        ixx="0.000884120311608432"
        ixy="-3.27280002046466E-05"
        ixz="-4.17903307138009E-06"
        iyy="0.00152701411958271"
        iyz="3.77556480315839E-10"
        izz="0.00126994685390396" />
    </inertial>
    <visual>
      <origin
        xyz="0 0 0"
        rpy="0 0 0" />
      <geometry>
        <mesh
          filename="package://description_pkg/meshes/MGT_IZQ.STL" />
      </geometry>
      <material
        name="">
        <color
          rgba="0.792156862745098 0.819607843137255 0.933333333333333 1" />
      </material>
    </visual>
    <collision>
      <origin
        xyz="0 0 0"
        rpy="0 0 0" />
      <geometry>
        <mesh
          filename="package://description_pkg/meshes/MGT_IZQ.STL" />
      </geometry>
    </collision>
  </link>

  <joint name="MGT_IZQ_joint" type="fixed">
    <origin
      xyz="0.15 0.35805 -0.078868"
      rpy="-1.5708 1.5606 1.5708" />
    <parent
      link="ST02_IZQ" />
    <child
      link="MGT_IZQ" />
    <axis
      xyz="0 0 0" />
  </joint>

<!-- RUEDA TRASERA IZQUIERDA -->

  <link name="ET_IZQ">
    <inertial>
      <origin
        xyz="-0.000700729202568251 -0.0241520014976043 -0.000245429077767367"
        rpy="0 0 0" />
      <mass
        value="31.2828656144139" />
      <inertia
        ixx="0.862804907337477"
        ixy="1.41722187809032E-05"
        ixz="1.98490047156525E-07"
        iyy="1.39717483715082"
        iyz="0.00543022765064057"
        izz="0.862811943500995" />
    </inertial>
    <visual>
      <origin
        xyz="0 0 0"
        rpy="0 0 0" />
      <geometry>
          <mesh
            filename="package://description_pkg/meshes/ET_IZQ.STL" />
        
      </geometry>
      <material
        name="">
        <color
          rgba="0.1 0.1 0.1 1" />
      </material>
    </visual>
    <collision>
      <origin
        xyz="0 -0.038 0"
        rpy="0 1.5707 1.5707" />
      <geometry>
        <cylinder radius="0.343" length="0.285"/>
      </geometry>
    </collision>
  </link>

  <joint name="ET_IZQ_joint" type="revolute">
    <origin
      xyz="0.067 -0.144 0"
      rpy="3.1314 1.5708 0" />
    <parent
      link="MGT_IZQ" />
    <child
      link="ET_IZQ" />
    <axis
      xyz="0 1 0" />
        <limit effort="1.0" velocity="5.0" lower="-10000000000000000" upper="10000000000000000"/>

  </joint>

<!--        #### EJE TRASERO DERECHA ####        -->

<!-- AMORTIGUADOR TRASERO DERECHO -->

  <link name="ST01_DCH">
    <inertial>
      <origin
        xyz="0.00850083095421039 -0.0657819927229779 -0.159438279696522"
        rpy="0 0 0" />
      <mass
        value="1.68652397926041" />
      <inertia
        ixx="0.00633380015599698"
        ixy="-1.45261475354718E-05"
        ixz="-3.52667266966141E-05"
        iyy="0.00552508031376817"
        iyz="-0.00194680915816559"
        izz="0.00160836691478164" />
    </inertial>
    <visual>
      <origin
        xyz="0 0 0"
        rpy="0 0 0" />
      <geometry>
        <mesh
          filename="package://description_pkg/meshes/ST01_DCH.STL" />
      </geometry>
      <material
        name="">
        <color
          rgba="0.752941176470588 0.752941176470588 0.752941176470588 1" />
      </material>
    </visual>
    <collision>
      <origin
        xyz="0 0 0"
        rpy="0 0 0" />
      <geometry>
        <mesh
          filename="package://description_pkg/meshes/ST01_DCH.STL" />
      </geometry>
    </collision>
  </link>

  <joint name="ST01_DCH_sup_joint" type="revolute">
    <origin
      xyz="-0.3275 0.66468 0.79122"
      rpy="0 0 -1.5708" />
    <parent
      link="CH" />
    <child
      link="ST01_DCH" />
    <axis
      xyz="1 0 0" />
    <limit effort="1.0" velocity="5.0" lower="-3.14" upper="3.14"/>
  </joint>

<!-- BRAZO SUPERIOR TRASERO DERECHO -->

  <link name="ST02_DCH">
    <inertial>
      <origin
        xyz="0.149999994832603 -0.174879151139789 -0.0332493411124751"
        rpy="0 0 0" />
      <mass
        value="0.816782909187793" />
      <inertia
        ixx="0.00805847541687784"
        ixy="9.94042593343271E-10"
        ixz="-4.39327267255029E-09"
        iyy="0.00136969060130727"
        iyz="-0.00150446688084042"
        izz="0.00869514722257053" />
    </inertial>
    <visual>
      <origin
        xyz="0 0 0"
        rpy="0 0 0" />
      <geometry>
        <mesh
          filename="package://description_pkg/meshes/ST02_DCH.STL" />
      </geometry>
      <material
        name="">
        <color
          rgba="0.752941176470588 0.752941176470588 0.752941176470588 1" />
      </material>
    </visual>
    <collision>
      <origin
        xyz="0 0 0"
        rpy="0 0 0" />
      <geometry>
        <mesh
          filename="package://description_pkg/meshes/ST02_DCH.STL" />
      </geometry>
    </collision>
  </link>

  <joint name="ST02_DCH_CH_joint" type="revolute">
    <origin
      xyz="-0.19 0.80618 0.45222"
      rpy="0 0 -1.5708" />
    <parent
      link="CH" />
    <child
      link="ST02_DCH" />
    <axis
      xyz="1 0 0" />
    <limit effort="1.0" velocity="5.0" lower="-3.14" upper="3.14"/>
  </joint>

<!-- BRAZO INFERIOR TRASERO DERECHO -->

  <link name="ST03_DCH">
    <inertial>
      <origin
        xyz="0.150000000000001 -0.164533605888152 -0.0525148439282279"
        rpy="0 0 0" />
      <mass
        value="0.341061626894354" />
      <inertia
        ixx="0.00227935928137914"
        ixy="3.80110151684503E-18"
        ixz="2.25386593134114E-18"
        iyy="0.000532010440822693"
        iyz="-0.000627611706469999"
        izz="0.00233995796668447" />
    </inertial>
    <visual>
      <origin
        xyz="0 0 0"
        rpy="0 0 0" />
      <geometry>
        <mesh
          filename="package://description_pkg/meshes/ST03_DCH.STL" />
      </geometry>
      <material
        name="">
        <color
          rgba="0.752941176470588 0.752941176470588 0.752941176470588 1" />
      </material>
    </visual>
    <collision>
      <origin
        xyz="0 0 0"
        rpy="0 0 0" />
      <geometry>
        <mesh
          filename="package://description_pkg/meshes/ST03_DCH.STL" />
      </geometry>
    </collision>
  </link>

  <joint name="ST03_DCH_CH_joint" type="revolute">
    <origin
      xyz="-0.178 0.80618 0.34222"
      rpy="0 0 -1.5708" />
    <parent
      link="CH" />
    <child
      link="ST03_DCH" />
    <axis
      xyz="1 0 0" />
    <limit effort="1.0" velocity="5.0" lower="-3.14" upper="3.14"/>
  </joint>


<!-- MANGUETA TRASERA DERECHA -->

  <link name="MGT_DCH">
    <inertial>
      <origin
        xyz="4.52389224525618E-07 0.113286548456591 -0.00345190812278645"
        rpy="0 0 0" />
      <mass
        value="0.586281219463848" />
      <inertia
        ixx="0.00134163383667941"
        ixy="4.27082614246778E-08"
        ixz="4.18056539755781E-06"
        iyy="0.00163581388758224"
        iyz="2.580804437242E-05"
        izz="0.000954188830725327" />
    </inertial>
    <visual>
      <origin
        xyz="0 0 0"
        rpy="0 0 0" />
      <geometry>
        <mesh
          filename="package://description_pkg/meshes/MGT_DCH.STL" />
      </geometry>
      <material
        name="">
        <color
          rgba="0.752941176470588 0.752941176470588 0.752941176470588 1" />
      </material>
    </visual>
    <collision>
      <origin
        xyz="0 0 0"
        rpy="0 0 0" />
      <geometry>
        <mesh
          filename="package://description_pkg/meshes/MGT_DCH.STL" />
      </geometry>
    </collision>
  </link>

  <joint name="MGT_DCH_joint" type="fixed">
    <origin
      xyz="0.15 -0.51022 -0.14431"
      rpy="0 0 0" />
    <parent
      link="ST02_DCH" />
    <child
      link="MGT_DCH" />
    <axis
      xyz="0 0 0" />
  </joint>

<!-- RUEDA TRASERA DERECHA -->

  <link name="ET_DCH">
    <inertial>
      <origin
        xyz="-0.000703773718821132 0.0238865488241629 -0.000242700430142184"
        rpy="0 0 0" />
      <mass
        value="31.147989855423" />
      <inertia
        ixx="0.862733322783274"
        ixy="-1.41751435672682E-05"
        ixz="-6.44850890575577E-09"
        iyy="1.39706663655937"
        iyz="-0.00542984633879409"
        izz="0.862741174394592" />
    </inertial>
    <visual>
      <origin
        xyz="0 0 0"
        rpy="1.5707 0 0" />
      <geometry>
        <mesh
          filename="package://description_pkg/meshes/ET_DCH.STL" />
      </geometry>
      <material
        name="">
        <color
          rgba="0.1 0.1 0.1 1" />
      </material>
    </visual>
    <collision>
      <origin
        xyz="0 0.025 0"
        rpy="0 1.5707 1.5707" />
      <geometry>
        <cylinder radius="0.343" length="0.285"/>
        
      </geometry>
    </collision>
  </link>

  <joint name="ET_DCH_joint" type="revolute">
    <origin
      xyz="0 0 0"
      rpy="0 0 0" />
    <parent
      link="MGT_DCH" />
    <child
      link="ET_DCH" />
    <axis
      xyz="0 1 0" />

    <limit effort="1.0" velocity="5.0" lower="-10000000000000000" upper="10000000000000000"/>

  </joint>


<!-- 
  <gazebo>
    <plugin name="ackermann_steering_plugin" filename="libAckermannSteeringPlugin.so">
      <steering_joint>MGD_IZQ_SUP_joint</steering_joint>
      <steering_joint>MGD_DCH_SUP_joint</steering_joint>
      <steering_ratio>1.0</steering_ratio>
      <max_steering_angle>0.5</max_steering_angle>
      <wheelbase>1.0</wheelbase>
    </plugin> 
  </gazebo>   -->

</robot>
